Workbook

Sheet KPI_Summary
A1: E-Commerce Sales & Customer Analytics: KPI summary
A2: Synthetic data created for portfolio use. Amounts in INR. Sales exclude Cancelled and Returned orders. Blue = value copied from Python, black = formula.
A4: KPI | B4: Value | C4: How it is calculated
A5: Total Revenue | B5: =SUM(Dashboard_Data!$H$2:$H$2015) -> 5.5465772e+08 | C5: Sum of quantity x price x (1 - discount)
A6: Total Profit | B6: =SUM(Dashboard_Data!$J$2:$J$2015) -> 1.0278721e+08 | C6: Revenue minus product cost
A7: Profit Margin | B7: =B6/B5 -> 0.18531647 | C7: Total profit / total revenue
A8: Total Orders | B8: =Monthly_Sales!B14 -> 91641 | C8: Distinct valid orders (from Monthly_Sales)
A9: Average Order Value | B9: =B5/B8 -> 6052.5062 | C9: Total revenue / total orders
A10: Customers with a Sale | B10: =COUNTIFS(Customer_Analysis!$E$25:$E$20024,">=1") -> 19710 | C10: Customers with at least 1 valid order
A11: Registered Customers | B11: =COUNTA(Customer_Analysis!$A$25:$A$20024) -> 20000 | C11: All customers in the customer table
A12: Repeat Customer Rate | B12: =Customer_Analysis!B22 -> 0.8180619 | C12: Customers with 2+ orders / customers with a sale
A13: Revenue per Customer | B13: =B5/B10 -> 28140.93 | C13: Total revenue / customers with a sale
A14: Average Delivery Days | B14: 4.42 | C14: Delivered orders with a valid delivery date (from Python)
A15: Delivered within 5 Days | B15: 0.7590906 | C15: Share of those orders (from Python)
A16: Average Rating | B16: 3.92 | C16: Mean of valid review ratings (from Python)
A18: Order status (all orders)
A19: Status | B19: Orders (from Python) | C19: % of Orders
A20: Delivered | B20: 89877 | C20: =B20/SUM($B$20:$B$24) -> 0.90030051
A21: Returned | B21: 4430 | C21: =B21/SUM($B$20:$B$24) -> 0.044375438
A22: Cancelled | B22: 3759 | C22: =B22/SUM($B$20:$B$24) -> 0.037654012
A23: Shipped | B23: 1318 | C23: =B23/SUM($B$20:$B$24) -> 0.013202444
A24: Processing | B24: 446 | C24: =B24/SUM($B$20:$B$24) -> 0.0044675949
A26: Cancellation + return rate | C26: =SUMIFS(C20:C24,A20:A24,"Cancelled")+SUMIFS(C20:C24,A20:A24,"Returned") -> 0.08202945
A28: Reconciliation checks (each sheet should add up to the same total revenue)
A29: Check | B29: Sheet total | C29: Result
A30: Monthly_Sales | B30: =Monthly_Sales!C14 -> 5.5465772e+08 | C30: =IF(ABS(B30-$B$5)<1,"OK","CHECK") -> OK
A31: Category_Analysis | B31: =Category_Analysis!B12 -> 5.5465772e+08 | C31: =IF(ABS(B31-$B$5)<1,"OK","CHECK") -> OK
A32: Geography | B32: =Geography!C25 -> 5.5465772e+08 | C32: =IF(ABS(B32-$B$5)<1,"OK","CHECK") -> OK
A33: Customer_Analysis | B33: =Customer_Analysis!C10 -> 5.5465772e+08 | C33: =IF(ABS(B33-$B$5)<1,"OK","CHECK") -> OK
A34: Product_Analysis | B34: =SUM(Product_Analysis!$G$12:$G$5011) -> 5.5465772e+08 | C34: =IF(ABS(B34-$B$5)<1,"OK","CHECK") -> OK

Sheet Dashboard_Data
A1: Month | B1: Category | C1: State | D1: Order_Lines | E1: Quantity | F1: Gross_Sales | G1: Discount_Amount | H1: Revenue | I1: Cost | J1: Profit
A2: 45658 | B2: Beauty & Personal Care | C2: Assam | D2: 9 | E2: 14 | F2: 11482.55 | G2: 715.46 | H2: 10767.11 | I2: 5622.27 | J2: 5144.84
A3: 45658 | B3: Beauty & Personal Care | C3: Bihar | D3: 16 | E3: 19 | F3: 14411.35 | G3: 2067.98 | H3: 12343.37 | I3: 6641.53 | J3: 5701.84
A4: 45658 | B4: Beauty & Personal Care | C4: Chandigarh | D4: 8 | E4: 16 | F4: 18304.9 | G4: 3353.77 | H4: 14951.13 | I4: 8851.65 | J4: 6099.48
A5: 45658 | B5: Beauty & Personal Care | C5: Delhi | D5: 103 | E5: 163 | F5: 135085.5 | G5: 19903.6 | H5: 115181.95 | I5: 63508.35 | J5: 51673.59
A6: 45658 | B6: Beauty & Personal Care | C6: Goa | D6: 13 | E6: 20 | F6: 18169.65 | G6: 1488.6 | H6: 16681.05 | I6: 7743.37 | J6: 8937.68
A7: 45658 | B7: Beauty & Personal Care | C7: Gujarat | D7: 76 | E7: 127 | F7: 103233.65 | G7: 11443.74 | H7: 91789.9 | I7: 47002.36 | J7: 44787.56
A8: 45658 | B8: Beauty & Personal Care | C8: Haryana | D8: 33 | E8: 55 | F8: 32193.95 | G8: 3016.27 | H8: 29177.7 | I8: 14721.26 | J8: 14456.41
A9: 45658 | B9: Beauty & Personal Care | C9: Jammu & Kashmir | D9: 7 | E9: 12 | F9: 15572.1 | G9: 2535.13 | H9: 13036.97 | I9: 6713.31 | J9: 6323.66
A10: 45658 | B10: Beauty & Personal Care | C10: Jharkhand | D10: 9 | E10: 14 | F10: 7629.45 | G10: 496.55 | H10: 7132.9 | I10: 3352.36 | J10: 3780.54
A11: 45658 | B11: Beauty & Personal Care | C11: Karnataka | D11: 67 | E11: 105 | F11: 69225.3 | G11: 6450.53 | H11: 62774.79 | I11: 32534.14 | J11: 30240.67
A12: 45658 | B12: Beauty & Personal Care | C12: Kerala | D12: 39 | E12: 58 | F12: 53752.25 | G12: 5593.71 | H12: 48158.54 | I12: 25417.99 | J12: 22740.55
A13: 45658 | B13: Beauty & Personal Care | C13: Madhya Pradesh | D13: 31 | E13: 48 | F13: 35326.2 | G13: 3821.72 | H13: 31504.48 | I13: 15710.36 | J13: 15794.13
... A2015: 45992 | B2015: Toys & Games | C2015: West Bengal | D2015: 57 | E2015: 79 | F2015: 72066.8 | G2015: 9290.78 | H2015: 62776.01 | I2015: 44427.56 | J2015: 18348.45

Sheet Monthly_Sales
A1: Month | B1: Orders (from Python) | C1: Revenue | D1: Profit | E1: Profit Margin | F1: Avg Order Value | G1: Growth vs Last Month | H1: Cumulative Revenue
A2: 45658 | B2: 4222 | C2: =SUMIFS(Dashboard_Data!$H$2:$H$2015,Dashboard_Data!$A$2:$A$2015,A2) -> 25397599 | D2: =SUMIFS(Dashboard_Data!$J$2:$J$2015,Dashboard_Data!$A$2:$A$2015,A2) -> 5029034.5 | E2: =IF(C2=0,0,D2/C2) -> 0.1980122 | F2: =IF(B2=0,0,C2/B2) -> 6015.5374 | H2: =SUM($C$2:C2) -> 25397599
A3: 45689 | B3: 3807 | C3: =SUMIFS(Dashboard_Data!$H$2:$H$2015,Dashboard_Data!$A$2:$A$2015,A3) -> 22102283 | D3: =SUMIFS(Dashboard_Data!$J$2:$J$2015,Dashboard_Data!$A$2:$A$2015,A3) -> 4350327.2 | E3: =IF(C3=0,0,D3/C3) -> 0.19682705 | F3: =IF(B3=0,0,C3/B3) -> 5805.6956 | G3: =IF(C2=0,0,C3/C2-1) -> -0.1297491 | H3: =SUM($C$2:C3) -> 47499882
A4: 45717 | B4: 5128 | C4: =SUMIFS(Dashboard_Data!$H$2:$H$2015,Dashboard_Data!$A$2:$A$2015,A4) -> 29320328 | D4: =SUMIFS(Dashboard_Data!$J$2:$J$2015,Dashboard_Data!$A$2:$A$2015,A4) -> 5688256 | E4: =IF(C4=0,0,D4/C4) -> 0.19400383 | F4: =IF(B4=0,0,C4/B4) -> 5717.6926 | G4: =IF(C3=0,0,C4/C3-1) -> 0.32657461 | H4: =SUM($C$2:C4) -> 76820210
A5: 45748 | B5: 5062 | C5: =SUMIFS(Dashboard_Data!$H$2:$H$2015,Dashboard_Data!$A$2:$A$2015,A5) -> 30834160 | D5: =SUMIFS(Dashboard_Data!$J$2:$J$2015,Dashboard_Data!$A$2:$A$2015,A5) -> 5923727.7 | E5: =IF(C5=0,0,D5/C5) -> 0.19211575 | F5: =IF(B5=0,0,C5/B5) -> 6091.2998 | G5: =IF(C4=0,0,C5/C4-1) -> 0.051630794 | H5: =SUM($C$2:C5) -> 1.0765437e+08
A6: 45778 | B6: 6065 | C6: =SUMIFS(Dashboard_Data!$H$2:$H$2015,Dashboard_Data!$A$2:$A$2015,A6) -> 37351036 | D6: =SUMIFS(Dashboard_Data!$J$2:$J$2015,Dashboard_Data!$A$2:$A$2015,A6) -> 7235656.9 | E6: =IF(C6=0,0,D6/C6) -> 0.19372038 | F6: =IF(B6=0,0,C6/B6) -> 6158.4561 | G6: =IF(C5=0,0,C6/C5-1) -> 0.2113525 | H6: =SUM($C$2:C6) -> 1.4500541e+08
A7: 45809 | B7: 5690 | C7: =SUMIFS(Dashboard_Data!$H$2:$H$2015,Dashboard_Data!$A$2:$A$2015,A7) -> 32397956 | D7: =SUMIFS(Dashboard_Data!$J$2:$J$2015,Dashboard_Data!$A$2:$A$2015,A7) -> 6333249.3 | E7: =IF(C7=0,0,D7/C7) -> 0.19548299 | F7: =IF(B7=0,0,C7/B7) -> 5693.8411 | G7: =IF(C6=0,0,C7/C6-1) -> -0.13260892 | H7: =SUM($C$2:C7) -> 1.7740336e+08
A8: 45839 | B8: 6473 | C8: =SUMIFS(Dashboard_Data!$H$2:$H$2015,Dashboard_Data!$A$2:$A$2015,A8) -> 38496649 | D8: =SUMIFS(Dashboard_Data!$J$2:$J$2015,Dashboard_Data!$A$2:$A$2015,A8) -> 7633083.5 | E8: =IF(C8=0,0,D8/C8) -> 0.19827917 | F8: =IF(B8=0,0,C8/B8) -> 5947.2654 | G8: =IF(C7=0,0,C8/C7-1) -> 0.18824315 | H8: =SUM($C$2:C8) -> 2.1590001e+08
A9: 45870 | B9: 8015 | C9: =SUMIFS(Dashboard_Data!$H$2:$H$2015,Dashboard_Data!$A$2:$A$2015,A9) -> 47965924 | D9: =SUMIFS(Dashboard_Data!$J$2:$J$2015,Dashboard_Data!$A$2:$A$2015,A9) -> 9293805.5 | E9: =IF(C9=0,0,D9/C9) -> 0.1937585 | F9: =IF(B9=0,0,C9/B9) -> 5984.5195 | G9: =IF(C8=0,0,C9/C8-1) -> 0.24597661 | H9: =SUM($C$2:C9) -> 2.6386593e+08
A10: 45901 | B10: 7876 | C10: =SUMIFS(Dashboard_Data!$H$2:$H$2015,Dashboard_Data!$A$2:$A$2015,A10) -> 46663727 | D10: =SUMIFS(Dashboard_Data!$J$2:$J$2015,Dashboard_Data!$A$2:$A$2015,A10) -> 9339527.3 | E10: =IF(C10=0,0,D10/C10) -> 0.20014533 | F10: =IF(B10=0,0,C10/B10) -> 5924.8003 | G10: =IF(C9=0,0,C10/C9-1) -> -0.027148372 | H10: =SUM($C$2:C10) -> 3.1052966e+08
A11: 45931 | B11: 12671 | C11: =SUMIFS(Dashboard_Data!$H$2:$H$2015,Dashboard_Data!$A$2:$A$2015,A11) -> 80057120 | D11: =SUMIFS(Dashboard_Data!$J$2:$J$2015,Dashboard_Data!$A$2:$A$2015,A11) -> 12961531 | E11: =IF(C11=0,0,D11/C11) -> 0.16190354 | F11: =IF(B11=0,0,C11/B11) -> 6318.1375 | G11: =IF(C10=0,0,C11/C10-1) -> 0.71561777 | H11: =SUM($C$2:C11) -> 3.9058678e+08
A12: 45962 | B12: 13527 | C12: =SUMIFS(Dashboard_Data!$H$2:$H$2015,Dashboard_Data!$A$2:$A$2015,A12) -> 85755948 | D12: =SUMIFS(Dashboard_Data!$J$2:$J$2015,Dashboard_Data!$A$2:$A$2015,A12) -> 13504872 | E12: =IF(C12=0,0,D12/C12) -> 0.15748029 | F12: =IF(B12=0,0,C12/B12) -> 6339.6132 | G12: =IF(C11=0,0,C12/C11-1) -> 0.071184527 | H12: =SUM($C$2:C12) -> 4.7634273e+08
A13: 45992 | B13: 13105 | C13: =SUMIFS(Dashboard_Data!$H$2:$H$2015,Dashboard_Data!$A$2:$A$2015,A13) -> 78314995 | D13: =SUMIFS(Dashboard_Data!$J$2:$J$2015,Dashboard_Data!$A$2:$A$2015,A13) -> 15494139 | E13: =IF(C13=0,0,D13/C13) -> 0.19784383 | F13: =IF(B13=0,0,C13/B13) -> 5975.963 | G13: =IF(C12=0,0,C13/C12-1) -> -0.086768948 | H13: =SUM($C$2:C13) -> 5.5465772e+08
A14: Total | B14: =SUM(B2:B13) -> 91641 | C14: =SUM(C2:C13) -> 5.5465772e+08 | D14: =SUM(D2:D13) -> 1.0278721e+08 | E14: =IF(C14=0,0,D14/C14) -> 0.18531647 | F14: =IF(B14=0,0,C14/B14) -> 6052.5062
A16: Orders are distinct order counts, so they cannot be rebuilt from the line-level Dashboard_Data table.

Sheet Category_Analysis
A1: Category performance (valid sales only)
A3: Category | B3: Revenue | C3: Profit | D3: Units Sold | E3: Profit Margin | F3: Revenue Share | G3: Revenue Rank | H3: Avg Discount | I3: Margin Check
A4: Electronics | B4: =SUMIFS(Dashboard_Data!$H$2:$H$2015,Dashboard_Data!$B$2:$B$2015,$A4) -> 3.0764453e+08 | C4: =SUMIFS(Dashboard_Data!$J$2:$J$2015,Dashboard_Data!$B$2:$B$2015,$A4) -> 27653058 | D4: =SUMIFS(Dashboard_Data!$E$2:$E$2015,Dashboard_Data!$B$2:$B$2015,$A4) -> 22212 | E4: =IF(B4=0,0,C4/B4) -> 0.089886397 | F4: =B4/$B$12 -> 0.55465653 | G4: =RANK(B4,$B$4:$B$11) -> 1 | H4: =SUMIFS(Dashboard_Data!$G$2:$G$2015,Dashboard_Data!$B$2:$B$2015,$A4)/SUMIFS(Dashboard_Data!$F$2:$F$2015,Dashboard_Data!$B$2:$B$2015,$A4) -> 0.081568306 | I4: =IF(E4<$E$12,"Below average margin","OK") -> Below average margin
A5: Home & Kitchen | B5: =SUMIFS(Dashboard_Data!$H$2:$H$2015,Dashboard_Data!$B$2:$B$2015,$A5) -> 1.0695085e+08 | C5: =SUMIFS(Dashboard_Data!$J$2:$J$2015,Dashboard_Data!$B$2:$B$2015,$A5) -> 27437439 | D5: =SUMIFS(Dashboard_Data!$E$2:$E$2015,Dashboard_Data!$B$2:$B$2015,$A5) -> 33717 | E5: =IF(B5=0,0,C5/B5) -> 0.25654251 | F5: =B5/$B$12 -> 0.19282315 | G5: =RANK(B5,$B$4:$B$11) -> 2 | H5: =SUMIFS(Dashboard_Data!$G$2:$G$2015,Dashboard_Data!$B$2:$B$2015,$A5)/SUMIFS(Dashboard_Data!$F$2:$F$2015,Dashboard_Data!$B$2:$B$2015,$A5) -> 0.1082632 | I5: =IF(E5<$E$12,"Below average margin","OK") -> OK
A6: Fashion | B6: =SUMIFS(Dashboard_Data!$H$2:$H$2015,Dashboard_Data!$B$2:$B$2015,$A6) -> 60510031 | C6: =SUMIFS(Dashboard_Data!$J$2:$J$2015,Dashboard_Data!$B$2:$B$2015,$A6) -> 23798691 | D6: =SUMIFS(Dashboard_Data!$E$2:$E$2015,Dashboard_Data!$B$2:$B$2015,$A6) -> 52619 | E6: =IF(B6=0,0,C6/B6) -> 0.39330159 | F6: =B6/$B$12 -> 0.10909436 | G6: =RANK(B6,$B$4:$B$11) -> 3 | H6: =SUMIFS(Dashboard_Data!$G$2:$G$2015,Dashboard_Data!$B$2:$B$2015,$A6)/SUMIFS(Dashboard_Data!$F$2:$F$2015,Dashboard_Data!$B$2:$B$2015,$A6) -> 0.17985008 | I6: =IF(E6<$E$12,"Below average margin","OK") -> OK
A7: Sports & Fitness | B7: =SUMIFS(Dashboard_Data!$H$2:$H$2015,Dashboard_Data!$B$2:$B$2015,$A7) -> 23856897 | C7: =SUMIFS(Dashboard_Data!$J$2:$J$2015,Dashboard_Data!$B$2:$B$2015,$A7) -> 7167866 | D7: =SUMIFS(Dashboard_Data!$E$2:$E$2015,Dashboard_Data!$B$2:$B$2015,$A7) -> 13256 | E7: =IF(B7=0,0,C7/B7) -> 0.30045256 | F7: =B7/$B$12 -> 0.043011927 | G7: =RANK(B7,$B$4:$B$11) -> 4 | H7: =SUMIFS(Dashboard_Data!$G$2:$G$2015,Dashboard_Data!$B$2:$B$2015,$A7)/SUMIFS(Dashboard_Data!$F$2:$F$2015,Dashboard_Data!$B$2:$B$2015,$A7) -> 0.10860036 | I7: =IF(E7<$E$12,"Below average margin","OK") -> OK
A8: Beauty & Personal Care | B8: =SUMIFS(Dashboard_Data!$H$2:$H$2015,Dashboard_Data!$B$2:$B$2015,$A8) -> 20646993 | C8: =SUMIFS(Dashboard_Data!$J$2:$J$2015,Dashboard_Data!$B$2:$B$2015,$A8) -> 9811707.2 | D8: =SUMIFS(Dashboard_Data!$E$2:$E$2015,Dashboard_Data!$B$2:$B$2015,$A8) -> 30080 | E8: =IF(B8=0,0,C8/B8) -> 0.4752124 | F8: =B8/$B$12 -> 0.037224747 | G8: =RANK(B8,$B$4:$B$11) -> 5 | H8: =SUMIFS(Dashboard_Data!$G$2:$G$2015,Dashboard_Data!$B$2:$B$2015,$A8)/SUMIFS(Dashboard_Data!$F$2:$F$2015,Dashboard_Data!$B$2:$B$2015,$A8) -> 0.11700176 | I8: =IF(E8<$E$12,"Below average margin","OK") -> OK
A9: Grocery | B9: =SUMIFS(Dashboard_Data!$H$2:$H$2015,Dashboard_Data!$B$2:$B$2015,$A9) -> 19484783 | C9: =SUMIFS(Dashboard_Data!$J$2:$J$2015,Dashboard_Data!$B$2:$B$2015,$A9) -> 2098079.4 | D9: =SUMIFS(Dashboard_Data!$E$2:$E$2015,Dashboard_Data!$B$2:$B$2015,$A9) -> 54712 | E9: =IF(B9=0,0,C9/B9) -> 0.10767784 | F9: =B9/$B$12 -> 0.035129382 | G9: =RANK(B9,$B$4:$B$11) -> 6 | H9: =SUMIFS(Dashboard_Data!$G$2:$G$2015,Dashboard_Data!$B$2:$B$2015,$A9)/SUMIFS(Dashboard_Data!$F$2:$F$2015,Dashboard_Data!$B$2:$B$2015,$A9) -> 0.046944526 | I9: =IF(E9<$E$12,"Below average margin","OK") -> Below average margin
A10: Toys & Games | B10: =SUMIFS(Dashboard_Data!$H$2:$H$2015,Dashboard_Data!$B$2:$B$2015,$A10) -> 8667706.8 | C10: =SUMIFS(Dashboard_Data!$J$2:$J$2015,Dashboard_Data!$B$2:$B$2015,$A10) -> 2601925.6 | D10: =SUMIFS(Dashboard_Data!$E$2:$E$2015,Dashboard_Data!$B$2:$B$2015,$A10) -> 10614 | E10: =IF(B10=0,0,C10/B10) -> 0.30018615 | F10: =B10/$B$12 -> 0.015627127 | G10: =RANK(B10,$B$4:$B$11) -> 7 | H10: =SUMIFS(Dashboard_Data!$G$2:$G$2015,Dashboard_Data!$B$2:$B$2015,$A10)/SUMIFS(Dashboard_Data!$F$2:$F$2015,Dashboard_Data!$B$2:$B$2015,$A10) -> 0.13378957 | I10: =IF(E10<$E$12,"Below average margin","OK") -> OK
A11: Books | B11: =SUMIFS(Dashboard_Data!$H$2:$H$2015,Dashboard_Data!$B$2:$B$2015,$A11) -> 6895938.3 | C11: =SUMIFS(Dashboard_Data!$J$2:$J$2015,Dashboard_Data!$B$2:$B$2015,$A11) -> 2218443.2 | D11: =SUMIFS(Dashboard_Data!$E$2:$E$2015,Dashboard_Data!$B$2:$B$2015,$A11) -> 18716 | E11: =IF(B11=0,0,C11/B11) -> 0.32170288 | F11: =B11/$B$12 -> 0.012432782 | G11: =RANK(B11,$B$4:$B$11) -> 8 | H11: =SUMIFS(Dashboard_Data!$G$2:$G$2015,Dashboard_Data!$B$2:$B$2015,$A11)/SUMIFS(Dashboard_Data!$F$2:$F$2015,Dashboard_Data!$B$2:$B$2015,$A11) -> 0.055315709 | I11: =IF(E11<$E$12,"Below average margin","OK") -> OK
A12: Total | B12: =SUM(B4:B11) -> 5.5465772e+08 | C12: =SUM(C4:C11) -> 1.0278721e+08 | D12: =SUM(D4:D11) -> 235926 | E12: =IF(B12=0,0,C12/B12) -> 0.18531647
A14: Revenue by category and month (pivot-style, SUMIFS)
A15: Category | B15: 45658 | C15: 45689 | D15: 45717 | E15: 45748 | F15: 45778 | G15: 45809 | H15: 45839 | I15: 45870 | J15: 45901 | K15: 45931 | L15: 45962 | M15: 45992 | N15: Total
A16: Electronics | B16: =SUMIFS(Dashboard_Data!$H$2:$H$2015,Dashboard_Data!$B$2:$B$2015,$A16,Dashboard_Data!$A$2:$A$2015,B$15) -> 13568342 | C16: =SUMIFS(Dashboard_Data!$H$2:$H$2015,Dashboard_Data!$B$2:$B$2015,$A16,Dashboard_Data!$A$2:$A$2015,C$15) -> 11515227 | D16: =SUMIFS(Dashboard_Data!$H$2:$H$2015,Dashboard_Data!$B$2:$B$2015,$A16,Dashboard_Data!$A$2:$A$2015,D$15) -> 15843944 | E16: =SUMIFS(Dashboard_Data!$H$2:$H$2015,Dashboard_Data!$B$2:$B$2015,$A16,Dashboard_Data!$A$2:$A$2015,E$15) -> 17013100 | F16: =SUMIFS(Dashboard_Data!$H$2:$H$2015,Dashboard_Data!$B$2:$B$2015,$A16,Dashboard_Data!$A$2:$A$2015,F$15) -> 20719022 | G16: =SUMIFS(Dashboard_Data!$H$2:$H$2015,Dashboard_Data!$B$2:$B$2015,$A16,Dashboard_Data!$A$2:$A$2015,G$15) -> 17263781 | H16: =SUMIFS(Dashboard_Data!$H$2:$H$2015,Dashboard_Data!$B$2:$B$2015,$A16,Dashboard_Data!$A$2:$A$2015,H$15) -> 20418349 | I16: =SUMIFS(Dashboard_Data!$H$2:$H$2015,Dashboard_Data!$B$2:$B$2015,$A16,Dashboard_Data!$A$2:$A$2015,I$15) -> 25762048 | ... M16: =SUMIFS(Dashboard_Data!$H$2:$H$2015,Dashboard_Data!$B$2:$B$2015,$A16,Dashboard_Data!$A$2:$A$2015,M$15) -> 42136015 | N16: =SUM(B16:M16) -> 3.0764453e+08
A17: Home & Kitchen | B17: =SUMIFS(Dashboard_Data!$H$2:$H$2015,Dashboard_Data!$B$2:$B$2015,$A17,Dashboard_Data!$A$2:$A$2015,B$15) -> 5251050.8 | C17: =SUMIFS(Dashboard_Data!$H$2:$H$2015,Dashboard_Data!$B$2:$B$2015,$A17,Dashboard_Data!$A$2:$A$2015,C$15) -> 4944813.3 | D17: =SUMIFS(Dashboard_Data!$H$2:$H$2015,Dashboard_Data!$B$2:$B$2015,$A17,Dashboard_Data!$A$2:$A$2015,D$15) -> 5725557.3 | E17: =SUMIFS(Dashboard_Data!$H$2:$H$2015,Dashboard_Data!$B$2:$B$2015,$A17,Dashboard_Data!$A$2:$A$2015,E$15) -> 6018073.4 | F17: =SUMIFS(Dashboard_Data!$H$2:$H$2015,Dashboard_Data!$B$2:$B$2015,$A17,Dashboard_Data!$A$2:$A$2015,F$15) -> 7403880.5 | G17: =SUMIFS(Dashboard_Data!$H$2:$H$2015,Dashboard_Data!$B$2:$B$2015,$A17,Dashboard_Data!$A$2:$A$2015,G$15) -> 6517118.6 | H17: =SUMIFS(Dashboard_Data!$H$2:$H$2015,Dashboard_Data!$B$2:$B$2015,$A17,Dashboard_Data!$A$2:$A$2015,H$15) -> 8071838.7 | I17: =SUMIFS(Dashboard_Data!$H$2:$H$2015,Dashboard_Data!$B$2:$B$2015,$A17,Dashboard_Data!$A$2:$A$2015,I$15) -> 9941277.3 | ... M17: =SUMIFS(Dashboard_Data!$H$2:$H$2015,Dashboard_Data!$B$2:$B$2015,$A17,Dashboard_Data!$A$2:$A$2015,M$15) -> 16058115 | N17: =SUM(B17:M17) -> 1.0695085e+08
A18: Fashion | B18: =SUMIFS(Dashboard_Data!$H$2:$H$2015,Dashboard_Data!$B$2:$B$2015,$A18,Dashboard_Data!$A$2:$A$2015,B$15) -> 2636392.7 | C18: =SUMIFS(Dashboard_Data!$H$2:$H$2015,Dashboard_Data!$B$2:$B$2015,$A18,Dashboard_Data!$A$2:$A$2015,C$15) -> 2371571.5 | D18: =SUMIFS(Dashboard_Data!$H$2:$H$2015,Dashboard_Data!$B$2:$B$2015,$A18,Dashboard_Data!$A$2:$A$2015,D$15) -> 3211019.5 | E18: =SUMIFS(Dashboard_Data!$H$2:$H$2015,Dashboard_Data!$B$2:$B$2015,$A18,Dashboard_Data!$A$2:$A$2015,E$15) -> 3152120 | F18: =SUMIFS(Dashboard_Data!$H$2:$H$2015,Dashboard_Data!$B$2:$B$2015,$A18,Dashboard_Data!$A$2:$A$2015,F$15) -> 3716780.5 | G18: =SUMIFS(Dashboard_Data!$H$2:$H$2015,Dashboard_Data!$B$2:$B$2015,$A18,Dashboard_Data!$A$2:$A$2015,G$15) -> 3565615.6 | H18: =SUMIFS(Dashboard_Data!$H$2:$H$2015,Dashboard_Data!$B$2:$B$2015,$A18,Dashboard_Data!$A$2:$A$2015,H$15) -> 4215786.5 | I18: =SUMIFS(Dashboard_Data!$H$2:$H$2015,Dashboard_Data!$B$2:$B$2015,$A18,Dashboard_Data!$A$2:$A$2015,I$15) -> 5018383.5 | ... M18: =SUMIFS(Dashboard_Data!$H$2:$H$2015,Dashboard_Data!$B$2:$B$2015,$A18,Dashboard_Data!$A$2:$A$2015,M$15) -> 8445534.4 | N18: =SUM(B18:M18) -> 60510031
A19: Sports & Fitness | B19: =SUMIFS(Dashboard_Data!$H$2:$H$2015,Dashboard_Data!$B$2:$B$2015,$A19,Dashboard_Data!$A$2:$A$2015,B$15) -> 1142896.4 | C19: =SUMIFS(Dashboard_Data!$H$2:$H$2015,Dashboard_Data!$B$2:$B$2015,$A19,Dashboard_Data!$A$2:$A$2015,C$15) -> 1002785.6 | D19: =SUMIFS(Dashboard_Data!$H$2:$H$2015,Dashboard_Data!$B$2:$B$2015,$A19,Dashboard_Data!$A$2:$A$2015,D$15) -> 1289443.5 | E19: =SUMIFS(Dashboard_Data!$H$2:$H$2015,Dashboard_Data!$B$2:$B$2015,$A19,Dashboard_Data!$A$2:$A$2015,E$15) -> 1486321.5 | F19: =SUMIFS(Dashboard_Data!$H$2:$H$2015,Dashboard_Data!$B$2:$B$2015,$A19,Dashboard_Data!$A$2:$A$2015,F$15) -> 1736702.6 | G19: =SUMIFS(Dashboard_Data!$H$2:$H$2015,Dashboard_Data!$B$2:$B$2015,$A19,Dashboard_Data!$A$2:$A$2015,G$15) -> 1441515 | H19: =SUMIFS(Dashboard_Data!$H$2:$H$2015,Dashboard_Data!$B$2:$B$2015,$A19,Dashboard_Data!$A$2:$A$2015,H$15) -> 1703722.5 | I19: =SUMIFS(Dashboard_Data!$H$2:$H$2015,Dashboard_Data!$B$2:$B$2015,$A19,Dashboard_Data!$A$2:$A$2015,I$15) -> 2237229.5 | ... M19: =SUMIFS(Dashboard_Data!$H$2:$H$2015,Dashboard_Data!$B$2:$B$2015,$A19,Dashboard_Data!$A$2:$A$2015,M$15) -> 3540567.3 | N19: =SUM(B19:M19) -> 23856897
A20: Beauty & Personal Care | B20: =SUMIFS(Dashboard_Data!$H$2:$H$2015,Dashboard_Data!$B$2:$B$2015,$A20,Dashboard_Data!$A$2:$A$2015,B$15) -> 1076787.6 | C20: =SUMIFS(Dashboard_Data!$H$2:$H$2015,Dashboard_Data!$B$2:$B$2015,$A20,Dashboard_Data!$A$2:$A$2015,C$15) -> 837478.18 | D20: =SUMIFS(Dashboard_Data!$H$2:$H$2015,Dashboard_Data!$B$2:$B$2015,$A20,Dashboard_Data!$A$2:$A$2015,D$15) -> 1186410.6 | E20: =SUMIFS(Dashboard_Data!$H$2:$H$2015,Dashboard_Data!$B$2:$B$2015,$A20,Dashboard_Data!$A$2:$A$2015,E$15) -> 1160633.2 | F20: =SUMIFS(Dashboard_Data!$H$2:$H$2015,Dashboard_Data!$B$2:$B$2015,$A20,Dashboard_Data!$A$2:$A$2015,F$15) -> 1396753.4 | G20: =SUMIFS(Dashboard_Data!$H$2:$H$2015,Dashboard_Data!$B$2:$B$2015,$A20,Dashboard_Data!$A$2:$A$2015,G$15) -> 1310028.7 | H20: =SUMIFS(Dashboard_Data!$H$2:$H$2015,Dashboard_Data!$B$2:$B$2015,$A20,Dashboard_Data!$A$2:$A$2015,H$15) -> 1516764.3 | I20: =SUMIFS(Dashboard_Data!$H$2:$H$2015,Dashboard_Data!$B$2:$B$2015,$A20,Dashboard_Data!$A$2:$A$2015,I$15) -> 1786533.4 | ... M20: =SUMIFS(Dashboard_Data!$H$2:$H$2015,Dashboard_Data!$B$2:$B$2015,$A20,Dashboard_Data!$A$2:$A$2015,M$15) -> 3071103.6 | N20: =SUM(B20:M20) -> 20646993
A21: Grocery | B21: =SUMIFS(Dashboard_Data!$H$2:$H$2015,Dashboard_Data!$B$2:$B$2015,$A21,Dashboard_Data!$A$2:$A$2015,B$15) -> 919325.49 | C21: =SUMIFS(Dashboard_Data!$H$2:$H$2015,Dashboard_Data!$B$2:$B$2015,$A21,Dashboard_Data!$A$2:$A$2015,C$15) -> 800474.11 | D21: =SUMIFS(Dashboard_Data!$H$2:$H$2015,Dashboard_Data!$B$2:$B$2015,$A21,Dashboard_Data!$A$2:$A$2015,D$15) -> 1210449 | E21: =SUMIFS(Dashboard_Data!$H$2:$H$2015,Dashboard_Data!$B$2:$B$2015,$A21,Dashboard_Data!$A$2:$A$2015,E$15) -> 1101965.2 | F21: =SUMIFS(Dashboard_Data!$H$2:$H$2015,Dashboard_Data!$B$2:$B$2015,$A21,Dashboard_Data!$A$2:$A$2015,F$15) -> 1313884.1 | G21: =SUMIFS(Dashboard_Data!$H$2:$H$2015,Dashboard_Data!$B$2:$B$2015,$A21,Dashboard_Data!$A$2:$A$2015,G$15) -> 1289673.7 | H21: =SUMIFS(Dashboard_Data!$H$2:$H$2015,Dashboard_Data!$B$2:$B$2015,$A21,Dashboard_Data!$A$2:$A$2015,H$15) -> 1432179.6 | I21: =SUMIFS(Dashboard_Data!$H$2:$H$2015,Dashboard_Data!$B$2:$B$2015,$A21,Dashboard_Data!$A$2:$A$2015,I$15) -> 1818731.8 | ... M21: =SUMIFS(Dashboard_Data!$H$2:$H$2015,Dashboard_Data!$B$2:$B$2015,$A21,Dashboard_Data!$A$2:$A$2015,M$15) -> 2674694.3 | N21: =SUM(B21:M21) -> 19484783
A22: Toys & Games | B22: =SUMIFS(Dashboard_Data!$H$2:$H$2015,Dashboard_Data!$B$2:$B$2015,$A22,Dashboard_Data!$A$2:$A$2015,B$15) -> 447069.41 | C22: =SUMIFS(Dashboard_Data!$H$2:$H$2015,Dashboard_Data!$B$2:$B$2015,$A22,Dashboard_Data!$A$2:$A$2015,C$15) -> 353733.69 | D22: =SUMIFS(Dashboard_Data!$H$2:$H$2015,Dashboard_Data!$B$2:$B$2015,$A22,Dashboard_Data!$A$2:$A$2015,D$15) -> 458928.35 | E22: =SUMIFS(Dashboard_Data!$H$2:$H$2015,Dashboard_Data!$B$2:$B$2015,$A22,Dashboard_Data!$A$2:$A$2015,E$15) -> 506897.12 | F22: =SUMIFS(Dashboard_Data!$H$2:$H$2015,Dashboard_Data!$B$2:$B$2015,$A22,Dashboard_Data!$A$2:$A$2015,F$15) -> 596580.07 | G22: =SUMIFS(Dashboard_Data!$H$2:$H$2015,Dashboard_Data!$B$2:$B$2015,$A22,Dashboard_Data!$A$2:$A$2015,G$15) -> 616290.22 | H22: =SUMIFS(Dashboard_Data!$H$2:$H$2015,Dashboard_Data!$B$2:$B$2015,$A22,Dashboard_Data!$A$2:$A$2015,H$15) -> 644727.19 | I22: =SUMIFS(Dashboard_Data!$H$2:$H$2015,Dashboard_Data!$B$2:$B$2015,$A22,Dashboard_Data!$A$2:$A$2015,I$15) -> 804930.99 | ... M22: =SUMIFS(Dashboard_Data!$H$2:$H$2015,Dashboard_Data!$B$2:$B$2015,$A22,Dashboard_Data!$A$2:$A$2015,M$15) -> 1340050.6 | N22: =SUM(B22:M22) -> 8667706.8
A23: Books | B23: =SUMIFS(Dashboard_Data!$H$2:$H$2015,Dashboard_Data!$B$2:$B$2015,$A23,Dashboard_Data!$A$2:$A$2015,B$15) -> 355734.87 | C23: =SUMIFS(Dashboard_Data!$H$2:$H$2015,Dashboard_Data!$B$2:$B$2015,$A23,Dashboard_Data!$A$2:$A$2015,C$15) -> 276199.57 | D23: =SUMIFS(Dashboard_Data!$H$2:$H$2015,Dashboard_Data!$B$2:$B$2015,$A23,Dashboard_Data!$A$2:$A$2015,D$15) -> 394575.3 | E23: =SUMIFS(Dashboard_Data!$H$2:$H$2015,Dashboard_Data!$B$2:$B$2015,$A23,Dashboard_Data!$A$2:$A$2015,E$15) -> 395049.48 | F23: =SUMIFS(Dashboard_Data!$H$2:$H$2015,Dashboard_Data!$B$2:$B$2015,$A23,Dashboard_Data!$A$2:$A$2015,F$15) -> 467432.77 | G23: =SUMIFS(Dashboard_Data!$H$2:$H$2015,Dashboard_Data!$B$2:$B$2015,$A23,Dashboard_Data!$A$2:$A$2015,G$15) -> 393932.69 | H23: =SUMIFS(Dashboard_Data!$H$2:$H$2015,Dashboard_Data!$B$2:$B$2015,$A23,Dashboard_Data!$A$2:$A$2015,H$15) -> 493281.29 | I23: =SUMIFS(Dashboard_Data!$H$2:$H$2015,Dashboard_Data!$B$2:$B$2015,$A23,Dashboard_Data!$A$2:$A$2015,I$15) -> 596789.21 | ... M23: =SUMIFS(Dashboard_Data!$H$2:$H$2015,Dashboard_Data!$B$2:$B$2015,$A23,Dashboard_Data!$A$2:$A$2015,M$15) -> 1048914.6 | N23: =SUM(B23:M23) -> 6895938.3

Sheet Product_Analysis
A1: Product performance (valid sales only)
A3: Product lookup
A4: Enter a product ID: | B4: P0092 | D4: Low revenue cutoff (10th percentile of selling products, from Python): | H4: 3895.66
A5: Product name | B5: =IFERROR(INDEX($B$12:$B$5011,MATCH($B$4,$A$12:$A$5011,0)),"Not found") -> Novo Laptop 15.6 inch Essential | D5: Products needing attention:
A6: Category | B6: =IFERROR(INDEX($C$12:$C$5011,MATCH($B$4,$A$12:$A$5011,0)),"Not found") -> Electronics | D6: No sales | E6: =COUNTIFS($K$12:$K$5011,D6) -> 155
A7: Revenue | B7: =IFERROR(INDEX($G$12:$G$5011,MATCH($B$4,$A$12:$A$5011,0)),"Not found") -> 6706553 | D7: Loss-making | E7: =COUNTIFS($K$12:$K$5011,D7) -> 17
A8: Profit | B8: =IFERROR(INDEX($H$12:$H$5011,MATCH($B$4,$A$12:$A$5011,0)),"Not found") -> 456596.37 | D8: Low revenue | E8: =COUNTIFS($K$12:$K$5011,D8) -> 483
A9: Excel 365 alternative: =XLOOKUP(B4, A12:A5011, B12:B5011) (INDEX/MATCH is used above because it works in every Excel version)
A11: Product ID | B11: Product Name | C11: Category | D11: Subcategory | E11: List Price | F11: Units Sold | G11: Revenue | H11: Profit | I11: Profit Margin | J11: Avg Selling Price | K11: Status
A12: P0001 | B12: Kiwa Smartphone 64GB Elite | C12: Electronics | D12: Smartphones | E12: 21149 | F12: 37 | G12: 710553.53 | H12: 28721.23 | I12: =IF(G12=0,0,H12/G12) -> 0.040420924 | J12: =IF(F12=0,0,G12/F12) -> 19204.149 | K12: =IF(G12=0,"No sales",IF(H12<0,"Loss-making",IF(G12<$H$4,"Low revenue","OK"))) -> OK
A13: P0002 | B13: Maple Lane Ultrabook Ultra | C13: Electronics | D13: Laptops | E13: 44739 | F13: 7 | G13: 274361.92 | H13: 5890.01 | I13: =IF(G13=0,0,H13/G13) -> 0.02146803 | J13: =IF(F13=0,0,G13/F13) -> 39194.56 | K13: =IF(G13=0,"No sales",IF(H13<0,"Loss-making",IF(G13<$H$4,"Low revenue","OK"))) -> OK
A14: P0003 | B14: Urbane Gaming Headset Prime | C14: Electronics | D14: Headphones & Earbuds | E14: 1259 | F14: 0 | G14: 0 | H14: 0 | I14: =IF(G14=0,0,H14/G14) -> 0 | J14: =IF(F14=0,0,G14/F14) -> 0 | K14: =IF(G14=0,"No sales",IF(H14<0,"Loss-making",IF(G14<$H$4,"Low revenue","OK"))) -> No sales
A15: P0004 | B15: Maple Lane Smart Watch Ultra | C15: Electronics | D15: Smart Watches | E15: 2169 | F15: 71 | G15: 141510.98 | H15: 17794.9 | I15: =IF(G15=0,0,H15/G15) -> 0.12574925 | J15: =IF(F15=0,0,G15/F15) -> 1993.1124 | K15: =IF(G15=0,"No sales",IF(H15<0,"Loss-making",IF(G15<$H$4,"Low revenue","OK"))) -> OK
A16: P0005 | B16: Bluepeak Smart TV 55 inch Essential | C16: Electronics | D16: Televisions | E16: 27039 | F16: 29 | G16: 735325.6 | H16: 93044.62 | I16: =IF(G16=0,0,H16/G16) -> 0.12653527 | J16: =IF(F16=0,0,G16/F16) -> 25356.055 | K16: =IF(G16=0,"No sales",IF(H16<0,"Loss-making",IF(G16<$H$4,"Low revenue","OK"))) -> OK
A17: P0006 | B17: Aurora Screen Guard Classic | C17: Electronics | D17: Mobile Accessories | E17: 769 | F17: 45 | G17: 31427.08 | H17: 3492.91 | I17: =IF(G17=0,0,H17/G17) -> 0.11114332 | J17: =IF(F17=0,0,G17/F17) -> 698.37956 | K17: =IF(G17=0,"No sales",IF(H17<0,"Loss-making",IF(G17<$H$4,"Low revenue","OK"))) -> OK
A18: P0007 | B18: Trueline 5G Smartphone Air | C18: Electronics | D18: Smartphones | E18: 18869 | F18: 10 | G18: 174632.6 | H18: 20925.79 | I18: =IF(G18=0,0,H18/G18) -> 0.11982751 | J18: =IF(F18=0,0,G18/F18) -> 17463.26 | K18: =IF(G18=0,"No sales",IF(H18<0,"Loss-making",IF(G18<$H$4,"Low revenue","OK"))) -> OK
A19: P0008 | B19: Maple Lane Laptop 14 inch Smart | C19: Electronics | D19: Laptops | E19: 48659 | F19: 1 | G19: 46226.05 | H19: 4389.91 | I19: =IF(G19=0,0,H19/G19) -> 0.09496615 | J19: =IF(F19=0,0,G19/F19) -> 46226.05 | K19: =IF(G19=0,"No sales",IF(H19<0,"Loss-making",IF(G19<$H$4,"Low revenue","OK"))) -> OK
A20: P0009 | B20: Ryko Neckband Earphones Max | C20: Electronics | D20: Headphones & Earbuds | E20: 1719 | F20: 19 | G20: 29648.45 | H20: 1553.15 | I20: =IF(G20=0,0,H20/G20) -> 0.052385538 | J20: =IF(F20=0,0,G20/F20) -> 1560.4447 | K20: =IF(G20=0,"No sales",IF(H20<0,"Loss-making",IF(G20<$H$4,"Low revenue","OK"))) -> OK
A21: P0010 | B21: Mosaic Fitness Band Essential | C21: Electronics | D21: Smart Watches | E21: 1079 | F21: 29 | G21: 29238.2 | H21: 2731.33 | I21: =IF(G21=0,0,H21/G21) -> 0.093416489 | J21: =IF(F21=0,0,G21/F21) -> 1008.2138 | K21: =IF(G21=0,"No sales",IF(H21<0,"Loss-making",IF(G21<$H$4,"Low revenue","OK"))) -> OK
A22: P0011 | B22: Mosaic Smart TV 55 inch Elite | C22: Electronics | D22: Televisions | E22: 17459 | F22: 53 | G22: 843575.24 | H22: 95843.84 | I22: =IF(G22=0,0,H22/G22) -> 0.11361623 | J22: =IF(F22=0,0,G22/F22) -> 15916.514 | K22: =IF(G22=0,"No sales",IF(H22<0,"Loss-making",IF(G22<$H$4,"Low revenue","OK"))) -> OK
A23: P0012 | B23: Zenix Screen Guard Pro | C23: Electronics | D23: Mobile Accessories | E23: 709 | F23: 22 | G23: 14559.3 | H23: 925.68 | I23: =IF(G23=0,0,H23/G23) -> 0.06357998 | J23: =IF(F23=0,0,G23/F23) -> 661.78636 | K23: =IF(G23=0,"No sales",IF(H23<0,"Loss-making",IF(G23<$H$4,"Low revenue","OK"))) -> OK
... A5011: P5000 | B5011: Amara Instant Noodles Pack Elite | C5011: Grocery | D5011: Packaged Foods | E5011: 109 | F5011: 2 | G5011: 218 | H5011: 37.18 | I5011: =IF(G5011=0,0,H5011/G5011) -> 0.17055046 | J5011: =IF(F5011=0,0,G5011/F5011) -> 109 | K5011: =IF(G5011=0,"No sales",IF(H5011<0,"Loss-making",IF(G5011<$H$4,"Low revenue","OK"))) -> Low revenue

Sheet Customer_Analysis
A1: Customer analysis
A3: Value segments (COUNTIFS / SUMIFS on the customer table below)
A4: Value Segment | B4: Customers | C4: Revenue | D4: Revenue per Customer | E4: % of Customers | F4: % of Revenue | G4: Avg Orders
A5: High Value | B5: =COUNTIFS($D$25:$D$20024,A5) -> 1913 | C5: =SUMIFS($F$25:$F$20024,$D$25:$D$20024,A5) -> 2.2958755e+08 | D5: =IF(B5=0,0,C5/B5) -> 120014.4 | E5: =B5/$B$10 -> 0.09565 | F5: =C5/$C$10 -> 0.41392653 | G5: =IF(B5=0,0,SUMIFS($E$25:$E$20024,$D$25:$D$20024,A5)/B5) -> 12.962363
A6: Regular | B6: =COUNTIFS($D$25:$D$20024,A6) -> 9447 | C6: =SUMIFS($F$25:$F$20024,$D$25:$D$20024,A6) -> 2.4006932e+08 | D6: =IF(B6=0,0,C6/B6) -> 25412.228 | E6: =B6/$B$10 -> 0.47235 | F6: =C6/$C$10 -> 0.43282427 | G6: =IF(B6=0,0,SUMIFS($E$25:$E$20024,$D$25:$D$20024,A6)/B6) -> 5.5143432
A7: Occasional | B7: =COUNTIFS($D$25:$D$20024,A7) -> 6391 | C7: =SUMIFS($F$25:$F$20024,$D$25:$D$20024,A7) -> 51919808 | D7: =IF(B7=0,0,C7/B7) -> 8123.8942 | E7: =B7/$B$10 -> 0.31955 | F7: =C7/$C$10 -> 0.093606932 | G7: =IF(B7=0,0,SUMIFS($E$25:$E$20024,$D$25:$D$20024,A7)/B7) -> 1.4412455
A8: At Risk | B8: =COUNTIFS($D$25:$D$20024,A8) -> 1959 | C8: =SUMIFS($F$25:$F$20024,$D$25:$D$20024,A8) -> 33081048 | D8: =IF(B8=0,0,C8/B8) -> 16886.701 | E8: =B8/$B$10 -> 0.09795 | F8: =C8/$C$10 -> 0.059642274 | G8: =IF(B8=0,0,SUMIFS($E$25:$E$20024,$D$25:$D$20024,A8)/B8) -> 2.827463
A9: Inactive | B9: =COUNTIFS($D$25:$D$20024,A9) -> 290 | C9: =SUMIFS($F$25:$F$20024,$D$25:$D$20024,A9) -> 0 | D9: =IF(B9=0,0,C9/B9) -> 0 | E9: =B9/$B$10 -> 0.0145 | F9: =C9/$C$10 -> 0 | G9: =IF(B9=0,0,SUMIFS($E$25:$E$20024,$D$25:$D$20024,A9)/B9) -> 0
A10: Total | B10: =SUM(B5:B9) -> 20000 | C10: =SUM(C5:C9) -> 5.5465772e+08
A12: Plan segments (chosen by the customer at signup)
A13: Plan Segment | B13: Customers | C13: Revenue | D13: Revenue per Customer
A14: Standard | B14: =COUNTIFS($C$25:$C$20024,A14) -> 11982 | C14: =SUMIFS($F$25:$F$20024,$C$25:$C$20024,A14) -> 2.9474884e+08 | D14: =IF(B14=0,0,C14/B14) -> 24599.302
A15: Premium | B15: =COUNTIFS($C$25:$C$20024,A15) -> 2988 | C15: =SUMIFS($F$25:$F$20024,$C$25:$C$20024,A15) -> 1.2779121e+08 | D15: =IF(B15=0,0,C15/B15) -> 42768.141
A16: Student | B16: =COUNTIFS($C$25:$C$20024,A16) -> 3032 | C16: =SUMIFS($F$25:$F$20024,$C$25:$C$20024,A16) -> 62409220 | D16: =IF(B16=0,0,C16/B16) -> 20583.516
A17: Business | B17: =COUNTIFS($C$25:$C$20024,A17) -> 1998 | C17: =SUMIFS($F$25:$F$20024,$C$25:$C$20024,A17) -> 69708461 | D17: =IF(B17=0,0,C17/B17) -> 34889.12
A19: Repeat customers (2+ valid orders)
A20: Customers with a sale | B20: =COUNTIFS($E$25:$E$20024,">=1") -> 19710
A21: Repeat customers | B21: =COUNTIFS($E$25:$E$20024,">=2") -> 16124
A22: Repeat customer rate | B22: =IF(B20=0,0,B21/B20) -> 0.8180619
A24: Customer ID | B24: State | C24: Plan Segment | D24: Value Segment | E24: Orders | F24: Revenue | G24: Days Since Last Order | H24: CLV Estimate (3 yr)
A25: C00001 | B25: Haryana | C25: Standard | D25: Regular | E25: 6 | F25: 16373.18 | G25: 7 | H25: 9102.66
A26: C00002 | B26: Delhi | C26: Standard | D26: Regular | E26: 5 | F26: 11215.9 | G26: 39 | H26: 6235.47
A27: C00003 | B27: Delhi | C27: Business | D27: Occasional | E27: 2 | F27: 2895.49 | G27: 38 | H27: 1609.75
A28: C00004 | B28: West Bengal | C28: Student | D28: Occasional | E28: 2 | F28: 22778.43 | G28: 21 | H28: 12663.65
A29: C00005 | B29: Maharashtra | C29: Standard | D29: Regular | E29: 3 | F29: 10178.1 | G29: 85 | H29: 5658.51
A30: C00006 | B30: Maharashtra | C30: Standard | D30: Occasional | E30: 1 | F30: 1258.29 | G30: 206 | H30: 699.55
A31: C00007 | B31: Karnataka | C31: Standard | D31: At Risk | E31: 2 | F31: 63847.1 | G31: 151 | H31: 35495.76
A32: C00008 | B32: Maharashtra | C32: Standard | D32: Occasional | E32: 1 | F32: 5277.71 | G32: 42 | H32: 2934.14
A33: C00009 | B33: Gujarat | C33: Student | D33: Occasional | E33: 2 | F33: 3446.16 | G33: 81 | H33: 1915.89
A34: C00010 | B34: Maharashtra | C34: Standard | D34: Regular | E34: 4 | F34: 5216.1 | G34: 54 | H34: 2899.89
A35: C00011 | B35: Delhi | C35: Student | D35: At Risk | E35: 2 | F35: 19125.2 | G35: 157 | H35: 10632.64
A36: C00012 | B36: Maharashtra | C36: Standard | D36: Occasional | E36: 2 | F36: 2409.4 | G36: 33 | H36: 1339.5
... A154: C00130 | B154: Madhya Pradesh | C154: Premium | D154: Regular | E154: 3 | F154: 11184.52 | G154: 72 | H154: 6218.03
A155: C00131 | B155: Telangana | C155: Business | D155: Inactive | E155: 0 | F155: 0 | H155: 0
A156: C00132 | B156: Maharashtra | C156: Standard | D156: Regular | E156: 8 | F156: 58214.67 | G156: 5 | H156: 32364.41
A157: C00133 | B157: Bihar | C157: Business | D157: Occasional | E157: 2 | F157: 2884.3 | G157: 107 | H157: 1603.52
A158: C00134 | B158: Kerala | C158: Standard | D158: Regular | E158: 7 | F158: 19905.74 | G158: 45 | H158: 11066.58
A159: C00135 | B159: Goa | C159: Standard | D159: Regular | E159: 4 | F159: 6137.85 | G159: 70 | H159: 3412.33
A160: C00136 | B160: Telangana | C160: Premium | D160: Occasional | E160: 2 | F160: 758.1 | G160: 105 | H160: 421.47
A161: C00137 | B161: Maharashtra | C161: Student | D161: Regular | E161: 3 | F161: 14007.77 | G161: 118 | H161: 7787.61
...

Sheet Geography
A1: Revenue by shipping state (valid sales only)
A3: State | B3: Orders (from Python) | C3: Revenue | D3: Profit | E3: Profit Margin | F3: Avg Order Value | G3: Revenue Share | H3: Cumulative Share | I3: Revenue Rank | J3: Market Size
A4: Maharashtra | B4: 13862 | C4: =SUMIFS(Dashboard_Data!$H$2:$H$2015,Dashboard_Data!$C$2:$C$2015,$A4) -> 86546459 | D4: =SUMIFS(Dashboard_Data!$J$2:$J$2015,Dashboard_Data!$C$2:$C$2015,$A4) -> 16100307 | E4: =IF(C4=0,0,D4/C4) -> 0.1860308 | F4: =IF(B4=0,0,C4/B4) -> 6243.4323 | G4: =C4/$C$25 -> 0.15603579 | H4: =SUM($G$4:G4) -> 0.15603579 | I4: =RANK(C4,$C$4:$C$24) -> 1 | J4: =IF(G4>=0.08,"Large",IF(G4>=0.03,"Medium","Small")) -> Large
A5: Delhi | B5: 8846 | C5: =SUMIFS(Dashboard_Data!$H$2:$H$2015,Dashboard_Data!$C$2:$C$2015,$A5) -> 54320410 | D5: =SUMIFS(Dashboard_Data!$J$2:$J$2015,Dashboard_Data!$C$2:$C$2015,$A5) -> 9855016.7 | E5: =IF(C5=0,0,D5/C5) -> 0.18142383 | F5: =IF(B5=0,0,C5/B5) -> 6140.6749 | G5: =C5/$C$25 -> 0.09793501 | H5: =SUM($G$4:G5) -> 0.2539708 | I5: =RANK(C5,$C$4:$C$24) -> 2 | J5: =IF(G5>=0.08,"Large",IF(G5>=0.03,"Medium","Small")) -> Large
A6: Karnataka | B6: 8420 | C6: =SUMIFS(Dashboard_Data!$H$2:$H$2015,Dashboard_Data!$C$2:$C$2015,$A6) -> 50249919 | D6: =SUMIFS(Dashboard_Data!$J$2:$J$2015,Dashboard_Data!$C$2:$C$2015,$A6) -> 9125699 | E6: =IF(C6=0,0,D6/C6) -> 0.18160624 | F6: =IF(B6=0,0,C6/B6) -> 5967.9239 | G6: =C6/$C$25 -> 0.090596267 | H6: =SUM($G$4:G6) -> 0.34456707 | I6: =RANK(C6,$C$4:$C$24) -> 3 | J6: =IF(G6>=0.08,"Large",IF(G6>=0.03,"Medium","Small")) -> Large
A7: Uttar Pradesh | B7: 8379 | C7: =SUMIFS(Dashboard_Data!$H$2:$H$2015,Dashboard_Data!$C$2:$C$2015,$A7) -> 48531035 | D7: =SUMIFS(Dashboard_Data!$J$2:$J$2015,Dashboard_Data!$C$2:$C$2015,$A7) -> 9241060 | E7: =IF(C7=0,0,D7/C7) -> 0.19041547 | F7: =IF(B7=0,0,C7/B7) -> 5791.9841 | G7: =C7/$C$25 -> 0.087497267 | H7: =SUM($G$4:G7) -> 0.43206434 | I7: =RANK(C7,$C$4:$C$24) -> 4 | J7: =IF(G7>=0.08,"Large",IF(G7>=0.03,"Medium","Small")) -> Large
A8: Gujarat | B8: 7201 | C8: =SUMIFS(Dashboard_Data!$H$2:$H$2015,Dashboard_Data!$C$2:$C$2015,$A8) -> 43939839 | D8: =SUMIFS(Dashboard_Data!$J$2:$J$2015,Dashboard_Data!$C$2:$C$2015,$A8) -> 8094681.2 | E8: =IF(C8=0,0,D8/C8) -> 0.18422191 | F8: =IF(B8=0,0,C8/B8) -> 6101.9079 | G8: =C8/$C$25 -> 0.079219736 | H8: =SUM($G$4:G8) -> 0.51128408 | I8: =RANK(C8,$C$4:$C$24) -> 5 | J8: =IF(G8>=0.08,"Large",IF(G8>=0.03,"Medium","Small")) -> Medium
A9: Tamil Nadu | B9: 6561 | C9: =SUMIFS(Dashboard_Data!$H$2:$H$2015,Dashboard_Data!$C$2:$C$2015,$A9) -> 39475862 | D9: =SUMIFS(Dashboard_Data!$J$2:$J$2015,Dashboard_Data!$C$2:$C$2015,$A9) -> 7410481.9 | E9: =IF(C9=0,0,D9/C9) -> 0.18772185 | F9: =IF(B9=0,0,C9/B9) -> 6016.7448 | G9: =C9/$C$25 -> 0.071171572 | H9: =SUM($G$4:G9) -> 0.58245565 | I9: =RANK(C9,$C$4:$C$24) -> 6 | J9: =IF(G9>=0.08,"Large",IF(G9>=0.03,"Medium","Small")) -> Medium
A10: Rajasthan | B10: 5449 | C10: =SUMIFS(Dashboard_Data!$H$2:$H$2015,Dashboard_Data!$C$2:$C$2015,$A10) -> 32246090 | D10: =SUMIFS(Dashboard_Data!$J$2:$J$2015,Dashboard_Data!$C$2:$C$2015,$A10) -> 6150461.9 | E10: =IF(C10=0,0,D10/C10) -> 0.19073512 | F10: =IF(B10=0,0,C10/B10) -> 5917.7996 | G10: =C10/$C$25 -> 0.058136917 | H10: =SUM($G$4:G10) -> 0.64059257 | I10: =RANK(C10,$C$4:$C$24) -> 7 | J10: =IF(G10>=0.08,"Large",IF(G10>=0.03,"Medium","Small")) -> Medium
A11: Telangana | B11: 4856 | C11: =SUMIFS(Dashboard_Data!$H$2:$H$2015,Dashboard_Data!$C$2:$C$2015,$A11) -> 29421088 | D11: =SUMIFS(Dashboard_Data!$J$2:$J$2015,Dashboard_Data!$C$2:$C$2015,$A11) -> 5477829.9 | E11: =IF(C11=0,0,D11/C11) -> 0.1861872 | F11: =IF(B11=0,0,C11/B11) -> 6058.7085 | G11: =C11/$C$25 -> 0.053043683 | H11: =SUM($G$4:G11) -> 0.69363625 | I11: =RANK(C11,$C$4:$C$24) -> 8 | J11: =IF(G11>=0.08,"Large",IF(G11>=0.03,"Medium","Small")) -> Medium
A12: West Bengal | B12: 4497 | C12: =SUMIFS(Dashboard_Data!$H$2:$H$2015,Dashboard_Data!$C$2:$C$2015,$A12) -> 27813989 | D12: =SUMIFS(Dashboard_Data!$J$2:$J$2015,Dashboard_Data!$C$2:$C$2015,$A12) -> 5037150.8 | E12: =IF(C12=0,0,D12/C12) -> 0.18110134 | F12: =IF(B12=0,0,C12/B12) -> 6185.0098 | G12: =C12/$C$25 -> 0.050146222 | H12: =SUM($G$4:G12) -> 0.74378247 | I12: =RANK(C12,$C$4:$C$24) -> 9 | J12: =IF(G12>=0.08,"Large",IF(G12>=0.03,"Medium","Small")) -> Medium
A13: Madhya Pradesh | B13: 4000 | C13: =SUMIFS(Dashboard_Data!$H$2:$H$2015,Dashboard_Data!$C$2:$C$2015,$A13) -> 24212149 | D13: =SUMIFS(Dashboard_Data!$J$2:$J$2015,Dashboard_Data!$C$2:$C$2015,$A13) -> 4454846.6 | E13: =IF(C13=0,0,D13/C13) -> 0.1839922 | F13: =IF(B13=0,0,C13/B13) -> 6053.0373 | G13: =C13/$C$25 -> 0.043652415 | H13: =SUM($G$4:G13) -> 0.78743489 | I13: =RANK(C13,$C$4:$C$24) -> 10 | J13: =IF(G13>=0.08,"Large",IF(G13>=0.03,"Medium","Small")) -> Medium
A14: Kerala | B14: 3971 | C14: =SUMIFS(Dashboard_Data!$H$2:$H$2015,Dashboard_Data!$C$2:$C$2015,$A14) -> 24175597 | D14: =SUMIFS(Dashboard_Data!$J$2:$J$2015,Dashboard_Data!$C$2:$C$2015,$A14) -> 4510266.3 | E14: =IF(C14=0,0,D14/C14) -> 0.18656277 | F14: =IF(B14=0,0,C14/B14) -> 6088.0376 | G14: =C14/$C$25 -> 0.043586515 | H14: =SUM($G$4:G14) -> 0.8310214 | I14: =RANK(C14,$C$4:$C$24) -> 11 | J14: =IF(G14>=0.08,"Large",IF(G14>=0.03,"Medium","Small")) -> Medium
A15: Haryana | B15: 3805 | C15: =SUMIFS(Dashboard_Data!$H$2:$H$2015,Dashboard_Data!$C$2:$C$2015,$A15) -> 23051877 | D15: =SUMIFS(Dashboard_Data!$J$2:$J$2015,Dashboard_Data!$C$2:$C$2015,$A15) -> 4213694.8 | E15: =IF(C15=0,0,D15/C15) -> 0.18279183 | F15: =IF(B15=0,0,C15/B15) -> 6058.312 | G15: =C15/$C$25 -> 0.041560544 | H15: =SUM($G$4:G15) -> 0.87258194 | I15: =RANK(C15,$C$4:$C$24) -> 12 | J15: =IF(G15>=0.08,"Large",IF(G15>=0.03,"Medium","Small")) -> Medium
... A24: Jammu & Kashmir | B24: 512 | C24: =SUMIFS(Dashboard_Data!$H$2:$H$2015,Dashboard_Data!$C$2:$C$2015,$A24) -> 2981914.9 | D24: =SUMIFS(Dashboard_Data!$J$2:$J$2015,Dashboard_Data!$C$2:$C$2015,$A24) -> 518721.19 | E24: =IF(C24=0,0,D24/C24) -> 0.17395573 | F24: =IF(B24=0,0,C24/B24) -> 5824.0526 | G24: =C24/$C$25 -> 0.0053761352 | H24: =SUM($G$4:G24) -> 1 | I24: =RANK(C24,$C$4:$C$24) -> 21 | J24: =IF(G24>=0.08,"Large",IF(G24>=0.03,"Medium","Small")) -> Small
A25: Total | B25: =SUM(B4:B24) -> 91641 | C25: =SUM(C4:C24) -> 5.5465772e+08 | D25: =SUM(D4:D24) -> 1.0278721e+08
